2024-11-16 13:46:26 - HypercubeAnalysis - INFO - Event: analysis_start
2024-11-16 13:46:26 - HypercubeAnalysis - INFO - Event: iteration_start
2024-11-16 13:46:26 - HypercubeAnalysis - ERROR - Error occurred with context
2024-11-16 13:46:26 - HypercubeAnalysis - ERROR - Uncaught exception:
Traceback (most recent call last):
  File "d:\Github\larsonPaperReplication\main.py", line 248, in <module>
    main()
  File "d:\Github\larsonPaperReplication\main.py", line 237, in main
    analysis.run_paper_replication()
  File "d:\Github\larsonPaperReplication\main.py", line 73, in run_paper_replication
    infinite_line = InfiniteLineModel(self.config)
                    ^^^^^^^^^^^^^^^^^^^^^^^^^^^^^^
  File "d:\Github\larsonPaperReplication\src\models\infinite_line_model.py", line 33, in __init__
    super().__init__(config)
  File "d:\Github\larsonPaperReplication\src\models\base_model.py", line 31, in __init__
    self.validate_config()
  File "d:\Github\larsonPaperReplication\src\models\base_model.py", line 62, in validate_config
    if self.config.N <= 0:
       ^^^^^^^^^^^^^
AttributeError: 'ModelConfig' object has no attribute 'N'
